[2024-06-06T16:19:54.605+0000] {local_task_job_runner.py:120} INFO - ::group::Pre task execution logs
[2024-06-06T16:19:54.620+0000] {taskinstance.py:2076} INFO - Dependencies all met for dep_context=non-requeueable deps ti=<TaskInstance: mongo_loader.load_clients manual__2024-06-06T16:19:54.149400+00:00 [queued]>
[2024-06-06T16:19:54.627+0000] {taskinstance.py:2076} INFO - Dependencies all met for dep_context=requeueable deps ti=<TaskInstance: mongo_loader.load_clients manual__2024-06-06T16:19:54.149400+00:00 [queued]>
[2024-06-06T16:19:54.627+0000] {taskinstance.py:2306} INFO - Starting attempt 1 of 1
[2024-06-06T16:19:54.635+0000] {taskinstance.py:2330} INFO - Executing <Task(PythonOperator): load_clients> on 2024-06-06 16:19:54.149400+00:00
[2024-06-06T16:19:54.638+0000] {warnings.py:110} WARNING - /home/***/.local/lib/python3.12/site-packages/***/task/task_runner/standard_task_runner.py:61: DeprecationWarning: This process (pid=367) is multi-threaded, use of fork() may lead to deadlocks in the child.
  pid = os.fork()

[2024-06-06T16:19:54.639+0000] {standard_task_runner.py:63} INFO - Started process 368 to run task
[2024-06-06T16:19:54.639+0000] {standard_task_runner.py:90} INFO - Running: ['***', 'tasks', 'run', 'mongo_loader', 'load_clients', 'manual__2024-06-06T16:19:54.149400+00:00', '--job-id', '27', '--raw', '--subdir', 'DAGS_FOLDER/load_mongo_dag.py', '--cfg-path', '/tmp/tmpsz3n2aej']
[2024-06-06T16:19:54.640+0000] {standard_task_runner.py:91} INFO - Job 27: Subtask load_clients
[2024-06-06T16:19:54.669+0000] {task_command.py:426} INFO - Running <TaskInstance: mongo_loader.load_clients manual__2024-06-06T16:19:54.149400+00:00 [running]> on host 945bac6cf142
[2024-06-06T16:19:54.713+0000] {taskinstance.py:2648} INFO - Exporting env vars: AIRFLOW_CTX_DAG_OWNER='***' AIRFLOW_CTX_DAG_ID='mongo_loader' AIRFLOW_CTX_TASK_ID='load_clients' AIRFLOW_CTX_EXECUTION_DATE='2024-06-06T16:19:54.149400+00:00' AIRFLOW_CTX_TRY_NUMBER='1' AIRFLOW_CTX_DAG_RUN_ID='manual__2024-06-06T16:19:54.149400+00:00'
[2024-06-06T16:19:54.714+0000] {taskinstance.py:430} INFO - ::endgroup::
[2024-06-06T16:19:54.727+0000] {base.py:84} INFO - Using connection ID 'mongo-etl' for task execution.
[2024-06-06T16:19:54.745+0000] {taskinstance.py:441} INFO - ::group::Post task execution logs
[2024-06-06T16:19:54.745+0000] {taskinstance.py:2905} ERROR - Task failed with exception
Traceback (most recent call last):
  File "/home/airflow/.local/lib/python3.12/site-packages/airflow/models/taskinstance.py", line 465, in _execute_task
    result = _execute_callable(context=context, **execute_callable_kwargs)
             ^^^^^^^^^^^^^^^^^^^^^^^^^^^^^^^^^^^^^^^^^^^^^^^^^^^^^^^^^^^^^
  File "/home/airflow/.local/lib/python3.12/site-packages/airflow/models/taskinstance.py", line 432, in _execute_callable
    return execute_callable(context=context, **execute_callable_kwargs)
           ^^^^^^^^^^^^^^^^^^^^^^^^^^^^^^^^^^^^^^^^^^^^^^^^^^^^^^^^^^^^
  File "/home/airflow/.local/lib/python3.12/site-packages/airflow/models/baseoperator.py", line 400, in wrapper
    return func(self, *args, **kwargs)
           ^^^^^^^^^^^^^^^^^^^^^^^^^^^
  File "/home/airflow/.local/lib/python3.12/site-packages/airflow/operators/python.py", line 235, in execute
    return_value = self.execute_callable()
                   ^^^^^^^^^^^^^^^^^^^^^^^
  File "/home/airflow/.local/lib/python3.12/site-packages/airflow/operators/python.py", line 252, in execute_callable
    return self.python_callable(*self.op_args, **self.op_kwargs)
           ^^^^^^^^^^^^^^^^^^^^^^^^^^^^^^^^^^^^^^^^^^^^^^^^^^^^^
  File "/opt/airflow/dags/load_mongo_dag.py", line 14, in load_clients
    return jsonify(list(clients_cursor))
           ^^^^^^^^^^^^^^^^^^^^^^^^^^^^^
  File "/home/airflow/.local/lib/python3.12/site-packages/flask/json/__init__.py", line 342, in jsonify
    return current_app.json.response(*args, **kwargs)
           ^^^^^^^^^^^^^^^^
  File "/home/airflow/.local/lib/python3.12/site-packages/werkzeug/local.py", line 316, in __get__
    obj = instance._get_current_object()
          ^^^^^^^^^^^^^^^^^^^^^^^^^^^^^^
  File "/home/airflow/.local/lib/python3.12/site-packages/werkzeug/local.py", line 513, in _get_current_object
    raise RuntimeError(unbound_message) from None
RuntimeError: Working outside of application context.

This typically means that you attempted to use functionality that needed
the current application. To solve this, set up an application context
with app.app_context(). See the documentation for more information.
[2024-06-06T16:19:54.752+0000] {taskinstance.py:1206} INFO - Marking task as FAILED. dag_id=mongo_loader, task_id=load_clients, run_id=manual__2024-06-06T16:19:54.149400+00:00, execution_date=20240606T161954, start_date=20240606T161954, end_date=20240606T161954
[2024-06-06T16:19:54.760+0000] {standard_task_runner.py:110} ERROR - Failed to execute job 27 for task load_clients (Working outside of application context.

This typically means that you attempted to use functionality that needed
the current application. To solve this, set up an application context
with app.app_context(). See the documentation for more information.; 368)
[2024-06-06T16:19:54.778+0000] {local_task_job_runner.py:240} INFO - Task exited with return code 1
[2024-06-06T16:19:54.789+0000] {taskinstance.py:3498} INFO - 0 downstream tasks scheduled from follow-on schedule check
[2024-06-06T16:19:54.791+0000] {local_task_job_runner.py:222} INFO - ::endgroup::
