[2024-06-08T15:41:41.441+0000] {local_task_job_runner.py:120} INFO - ::group::Pre task execution logs
[2024-06-08T15:41:41.455+0000] {taskinstance.py:2076} INFO - Dependencies all met for dep_context=non-requeueable deps ti=<TaskInstance: pg_loader.load_clients manual__2024-06-08T15:41:40.885291+00:00 [queued]>
[2024-06-08T15:41:41.460+0000] {taskinstance.py:2076} INFO - Dependencies all met for dep_context=requeueable deps ti=<TaskInstance: pg_loader.load_clients manual__2024-06-08T15:41:40.885291+00:00 [queued]>
[2024-06-08T15:41:41.460+0000] {taskinstance.py:2306} INFO - Starting attempt 1 of 1
[2024-06-08T15:41:41.468+0000] {taskinstance.py:2330} INFO - Executing <Task(PythonOperator): load_clients> on 2024-06-08 15:41:40.885291+00:00
[2024-06-08T15:41:41.472+0000] {warnings.py:110} WARNING - /home/***/.local/lib/python3.12/site-packages/***/task/task_runner/standard_task_runner.py:61: DeprecationWarning: This process (pid=793) is multi-threaded, use of fork() may lead to deadlocks in the child.
  pid = os.fork()

[2024-06-08T15:41:41.472+0000] {standard_task_runner.py:90} INFO - Running: ['***', 'tasks', 'run', 'pg_loader', 'load_clients', 'manual__2024-06-08T15:41:40.885291+00:00', '--job-id', '36', '--raw', '--subdir', 'DAGS_FOLDER/load_pg_dag.py', '--cfg-path', '/tmp/tmpw1392_i9']
[2024-06-08T15:41:41.473+0000] {standard_task_runner.py:63} INFO - Started process 794 to run task
[2024-06-08T15:41:41.473+0000] {standard_task_runner.py:91} INFO - Job 36: Subtask load_clients
[2024-06-08T15:41:41.500+0000] {task_command.py:426} INFO - Running <TaskInstance: pg_loader.load_clients manual__2024-06-08T15:41:40.885291+00:00 [running]> on host 945bac6cf142
[2024-06-08T15:41:41.549+0000] {taskinstance.py:2648} INFO - Exporting env vars: AIRFLOW_CTX_DAG_OWNER='***' AIRFLOW_CTX_DAG_ID='pg_loader' AIRFLOW_CTX_TASK_ID='load_clients' AIRFLOW_CTX_EXECUTION_DATE='2024-06-08T15:41:40.885291+00:00' AIRFLOW_CTX_TRY_NUMBER='1' AIRFLOW_CTX_DAG_RUN_ID='manual__2024-06-08T15:41:40.885291+00:00'
[2024-06-08T15:41:41.550+0000] {taskinstance.py:430} INFO - ::endgroup::
[2024-06-08T15:41:41.565+0000] {base.py:84} INFO - Using connection ID '***-etl' for task execution.
[2024-06-08T15:41:41.570+0000] {taskinstance.py:441} INFO - ::group::Post task execution logs
[2024-06-08T15:41:41.571+0000] {taskinstance.py:2905} ERROR - Task failed with exception
Traceback (most recent call last):
  File "/home/airflow/.local/lib/python3.12/site-packages/airflow/models/taskinstance.py", line 465, in _execute_task
    result = _execute_callable(context=context, **execute_callable_kwargs)
             ^^^^^^^^^^^^^^^^^^^^^^^^^^^^^^^^^^^^^^^^^^^^^^^^^^^^^^^^^^^^^
  File "/home/airflow/.local/lib/python3.12/site-packages/airflow/models/taskinstance.py", line 432, in _execute_callable
    return execute_callable(context=context, **execute_callable_kwargs)
           ^^^^^^^^^^^^^^^^^^^^^^^^^^^^^^^^^^^^^^^^^^^^^^^^^^^^^^^^^^^^
  File "/home/airflow/.local/lib/python3.12/site-packages/airflow/models/baseoperator.py", line 400, in wrapper
    return func(self, *args, **kwargs)
           ^^^^^^^^^^^^^^^^^^^^^^^^^^^
  File "/home/airflow/.local/lib/python3.12/site-packages/airflow/operators/python.py", line 235, in execute
    return_value = self.execute_callable()
                   ^^^^^^^^^^^^^^^^^^^^^^^
  File "/home/airflow/.local/lib/python3.12/site-packages/airflow/operators/python.py", line 252, in execute_callable
    return self.python_callable(*self.op_args, **self.op_kwargs)
           ^^^^^^^^^^^^^^^^^^^^^^^^^^^^^^^^^^^^^^^^^^^^^^^^^^^^^
  File "/opt/airflow/dags/load_pg_dag.py", line 14, in load_clients
    pg_cursor.execute('SELECT * FROM client')
psycopg2.errors.UndefinedTable: relation "client" does not exist
LINE 1: SELECT * FROM client
                      ^

[2024-06-08T15:41:41.579+0000] {taskinstance.py:1206} INFO - Marking task as FAILED. dag_id=pg_loader, task_id=load_clients, run_id=manual__2024-06-08T15:41:40.885291+00:00, execution_date=20240608T154140, start_date=20240608T154141, end_date=20240608T154141
[2024-06-08T15:41:41.586+0000] {standard_task_runner.py:110} ERROR - Failed to execute job 36 for task load_clients (relation "client" does not exist
LINE 1: SELECT * FROM client
                      ^
; 794)
[2024-06-08T15:41:41.612+0000] {local_task_job_runner.py:240} INFO - Task exited with return code 1
[2024-06-08T15:41:41.622+0000] {taskinstance.py:3498} INFO - 0 downstream tasks scheduled from follow-on schedule check
[2024-06-08T15:41:41.623+0000] {local_task_job_runner.py:222} INFO - ::endgroup::
