[2024-06-08T15:47:30.220+0000] {local_task_job_runner.py:120} INFO - ::group::Pre task execution logs
[2024-06-08T15:47:30.234+0000] {taskinstance.py:2076} INFO - Dependencies all met for dep_context=non-requeueable deps ti=<TaskInstance: pg_loader.load_clients manual__2024-06-08T15:47:29.950009+00:00 [queued]>
[2024-06-08T15:47:30.238+0000] {taskinstance.py:2076} INFO - Dependencies all met for dep_context=requeueable deps ti=<TaskInstance: pg_loader.load_clients manual__2024-06-08T15:47:29.950009+00:00 [queued]>
[2024-06-08T15:47:30.239+0000] {taskinstance.py:2306} INFO - Starting attempt 1 of 1
[2024-06-08T15:47:30.246+0000] {taskinstance.py:2330} INFO - Executing <Task(PythonOperator): load_clients> on 2024-06-08 15:47:29.950009+00:00
[2024-06-08T15:47:30.250+0000] {warnings.py:110} WARNING - /home/***/.local/lib/python3.12/site-packages/***/task/task_runner/standard_task_runner.py:61: DeprecationWarning: This process (pid=877) is multi-threaded, use of fork() may lead to deadlocks in the child.
  pid = os.fork()

[2024-06-08T15:47:30.250+0000] {standard_task_runner.py:90} INFO - Running: ['***', 'tasks', 'run', 'pg_loader', 'load_clients', 'manual__2024-06-08T15:47:29.950009+00:00', '--job-id', '39', '--raw', '--subdir', 'DAGS_FOLDER/load_pg_dag.py', '--cfg-path', '/tmp/tmp5k_tt515']
[2024-06-08T15:47:30.251+0000] {standard_task_runner.py:63} INFO - Started process 878 to run task
[2024-06-08T15:47:30.251+0000] {standard_task_runner.py:91} INFO - Job 39: Subtask load_clients
[2024-06-08T15:47:30.278+0000] {task_command.py:426} INFO - Running <TaskInstance: pg_loader.load_clients manual__2024-06-08T15:47:29.950009+00:00 [running]> on host 945bac6cf142
[2024-06-08T15:47:30.325+0000] {taskinstance.py:2648} INFO - Exporting env vars: AIRFLOW_CTX_DAG_OWNER='***' AIRFLOW_CTX_DAG_ID='pg_loader' AIRFLOW_CTX_TASK_ID='load_clients' AIRFLOW_CTX_EXECUTION_DATE='2024-06-08T15:47:29.950009+00:00' AIRFLOW_CTX_TRY_NUMBER='1' AIRFLOW_CTX_DAG_RUN_ID='manual__2024-06-08T15:47:29.950009+00:00'
[2024-06-08T15:47:30.326+0000] {taskinstance.py:430} INFO - ::endgroup::
[2024-06-08T15:47:30.338+0000] {base.py:84} INFO - Using connection ID '***-etl' for task execution.
[2024-06-08T15:47:30.343+0000] {taskinstance.py:441} INFO - ::group::Post task execution logs
[2024-06-08T15:47:30.344+0000] {taskinstance.py:2905} ERROR - Task failed with exception
Traceback (most recent call last):
  File "/home/airflow/.local/lib/python3.12/site-packages/airflow/models/taskinstance.py", line 465, in _execute_task
    result = _execute_callable(context=context, **execute_callable_kwargs)
             ^^^^^^^^^^^^^^^^^^^^^^^^^^^^^^^^^^^^^^^^^^^^^^^^^^^^^^^^^^^^^
  File "/home/airflow/.local/lib/python3.12/site-packages/airflow/models/taskinstance.py", line 432, in _execute_callable
    return execute_callable(context=context, **execute_callable_kwargs)
           ^^^^^^^^^^^^^^^^^^^^^^^^^^^^^^^^^^^^^^^^^^^^^^^^^^^^^^^^^^^^
  File "/home/airflow/.local/lib/python3.12/site-packages/airflow/models/baseoperator.py", line 400, in wrapper
    return func(self, *args, **kwargs)
           ^^^^^^^^^^^^^^^^^^^^^^^^^^^
  File "/home/airflow/.local/lib/python3.12/site-packages/airflow/operators/python.py", line 235, in execute
    return_value = self.execute_callable()
                   ^^^^^^^^^^^^^^^^^^^^^^^
  File "/home/airflow/.local/lib/python3.12/site-packages/airflow/operators/python.py", line 252, in execute_callable
    return self.python_callable(*self.op_args, **self.op_kwargs)
           ^^^^^^^^^^^^^^^^^^^^^^^^^^^^^^^^^^^^^^^^^^^^^^^^^^^^^
  File "/opt/airflow/dags/load_pg_dag.py", line 22, in load_clients
    pg_cursor.execute(
psycopg2.errors.InvalidColumnReference: there is no unique or exclusion constraint matching the ON CONFLICT specification

[2024-06-08T15:47:30.351+0000] {taskinstance.py:1206} INFO - Marking task as FAILED. dag_id=pg_loader, task_id=load_clients, run_id=manual__2024-06-08T15:47:29.950009+00:00, execution_date=20240608T154729, start_date=20240608T154730, end_date=20240608T154730
[2024-06-08T15:47:30.359+0000] {standard_task_runner.py:110} ERROR - Failed to execute job 39 for task load_clients (there is no unique or exclusion constraint matching the ON CONFLICT specification
; 878)
[2024-06-08T15:47:30.390+0000] {local_task_job_runner.py:240} INFO - Task exited with return code 1
[2024-06-08T15:47:30.400+0000] {taskinstance.py:3498} INFO - 0 downstream tasks scheduled from follow-on schedule check
[2024-06-08T15:47:30.402+0000] {local_task_job_runner.py:222} INFO - ::endgroup::
