[2024-06-06T15:13:38.840+0000] {local_task_job_runner.py:120} INFO - ::group::Pre task execution logs
[2024-06-06T15:13:38.853+0000] {taskinstance.py:2076} INFO - Dependencies all met for dep_context=non-requeueable deps ti=<TaskInstance: pg_loader.load_logs manual__2024-06-06T15:13:38.157495+00:00 [queued]>
[2024-06-06T15:13:38.858+0000] {taskinstance.py:2076} INFO - Dependencies all met for dep_context=requeueable deps ti=<TaskInstance: pg_loader.load_logs manual__2024-06-06T15:13:38.157495+00:00 [queued]>
[2024-06-06T15:13:38.860+0000] {taskinstance.py:2306} INFO - Starting attempt 1 of 1
[2024-06-06T15:13:38.868+0000] {taskinstance.py:2330} INFO - Executing <Task(PythonOperator): load_logs> on 2024-06-06 15:13:38.157495+00:00
[2024-06-06T15:13:38.872+0000] {warnings.py:110} WARNING - /home/***/.local/lib/python3.12/site-packages/***/task/task_runner/standard_task_runner.py:61: DeprecationWarning: This process (pid=703) is multi-threaded, use of fork() may lead to deadlocks in the child.
  pid = os.fork()

[2024-06-06T15:13:38.872+0000] {standard_task_runner.py:63} INFO - Started process 704 to run task
[2024-06-06T15:13:38.872+0000] {standard_task_runner.py:90} INFO - Running: ['***', 'tasks', 'run', 'pg_loader', 'load_logs', 'manual__2024-06-06T15:13:38.157495+00:00', '--job-id', '15', '--raw', '--subdir', 'DAGS_FOLDER/load_pg_dag.py', '--cfg-path', '/tmp/tmpf62aurv_']
[2024-06-06T15:13:38.874+0000] {standard_task_runner.py:91} INFO - Job 15: Subtask load_logs
[2024-06-06T15:13:38.901+0000] {task_command.py:426} INFO - Running <TaskInstance: pg_loader.load_logs manual__2024-06-06T15:13:38.157495+00:00 [running]> on host 945bac6cf142
[2024-06-06T15:13:38.948+0000] {taskinstance.py:2648} INFO - Exporting env vars: AIRFLOW_CTX_DAG_OWNER='***' AIRFLOW_CTX_DAG_ID='pg_loader' AIRFLOW_CTX_TASK_ID='load_logs' AIRFLOW_CTX_EXECUTION_DATE='2024-06-06T15:13:38.157495+00:00' AIRFLOW_CTX_TRY_NUMBER='1' AIRFLOW_CTX_DAG_RUN_ID='manual__2024-06-06T15:13:38.157495+00:00'
[2024-06-06T15:13:38.949+0000] {taskinstance.py:430} INFO - ::endgroup::
[2024-06-06T15:13:38.969+0000] {base.py:84} INFO - Using connection ID '***-etl' for task execution.
[2024-06-06T15:13:38.973+0000] {taskinstance.py:441} INFO - ::group::Post task execution logs
[2024-06-06T15:13:38.973+0000] {taskinstance.py:2905} ERROR - Task failed with exception
Traceback (most recent call last):
  File "/home/airflow/.local/lib/python3.12/site-packages/airflow/models/taskinstance.py", line 465, in _execute_task
    result = _execute_callable(context=context, **execute_callable_kwargs)
             ^^^^^^^^^^^^^^^^^^^^^^^^^^^^^^^^^^^^^^^^^^^^^^^^^^^^^^^^^^^^^
  File "/home/airflow/.local/lib/python3.12/site-packages/airflow/models/taskinstance.py", line 432, in _execute_callable
    return execute_callable(context=context, **execute_callable_kwargs)
           ^^^^^^^^^^^^^^^^^^^^^^^^^^^^^^^^^^^^^^^^^^^^^^^^^^^^^^^^^^^^
  File "/home/airflow/.local/lib/python3.12/site-packages/airflow/models/baseoperator.py", line 400, in wrapper
    return func(self, *args, **kwargs)
           ^^^^^^^^^^^^^^^^^^^^^^^^^^^
  File "/home/airflow/.local/lib/python3.12/site-packages/airflow/operators/python.py", line 235, in execute
    return_value = self.execute_callable()
                   ^^^^^^^^^^^^^^^^^^^^^^^
  File "/home/airflow/.local/lib/python3.12/site-packages/airflow/operators/python.py", line 252, in execute_callable
    return self.python_callable(*self.op_args, **self.op_kwargs)
           ^^^^^^^^^^^^^^^^^^^^^^^^^^^^^^^^^^^^^^^^^^^^^^^^^^^^^
  File "/opt/airflow/dags/load_pg_dag.py", line 10, in load_logs
    pg_conn = pg_hook.get_conn()
              ^^^^^^^^^^^^^^^^^^
  File "/home/airflow/.local/lib/python3.12/site-packages/airflow/providers/postgres/hooks/postgres.py", line 161, in get_conn
    self.conn = psycopg2.connect(**conn_args)
                ^^^^^^^^^^^^^^^^^^^^^^^^^^^^^
  File "/home/airflow/.local/lib/python3.12/site-packages/psycopg2/__init__.py", line 122, in connect
    conn = _connect(dsn, connection_factory=connection_factory, **kwasync)
           ^^^^^^^^^^^^^^^^^^^^^^^^^^^^^^^^^^^^^^^^^^^^^^^^^^^^^^^^^^^^^^^
psycopg2.OperationalError: connection to server at "***-etl" (172.27.0.3), port 5432 failed: FATAL:  database "public" does not exist

[2024-06-06T15:13:38.980+0000] {taskinstance.py:1206} INFO - Marking task as FAILED. dag_id=pg_loader, task_id=load_logs, run_id=manual__2024-06-06T15:13:38.157495+00:00, execution_date=20240606T151338, start_date=20240606T151338, end_date=20240606T151338
[2024-06-06T15:13:38.988+0000] {standard_task_runner.py:110} ERROR - Failed to execute job 15 for task load_logs (connection to server at "***-etl" (172.27.0.3), port 5432 failed: FATAL:  database "public" does not exist
; 704)
[2024-06-06T15:13:39.012+0000] {local_task_job_runner.py:240} INFO - Task exited with return code 1
[2024-06-06T15:13:39.022+0000] {taskinstance.py:3498} INFO - 0 downstream tasks scheduled from follow-on schedule check
[2024-06-06T15:13:39.023+0000] {local_task_job_runner.py:222} INFO - ::endgroup::
